INFO 2025-07-12 15:11:51,846 autoreload Watching for file changes with StatReloader
WARNING 2025-07-12 15:11:58,656 log Not Found: /
WARNING 2025-07-12 15:11:58,656 basehttp "GET / HTTP/1.1" 404 2309
WARNING 2025-07-12 15:11:59,392 log Not Found: /favicon.ico
WARNING 2025-07-12 15:11:59,393 basehttp "GET /favicon.ico HTTP/1.1" 404 2360
WARNING 2025-07-12 15:12:34,417 log Not Found: /blog/
WARNING 2025-07-12 15:12:34,417 basehttp "GET /blog/ HTTP/1.1" 404 3347
WARNING 2025-07-12 15:12:52,555 log Not Found: /api/cache/stats/
WARNING 2025-07-12 15:12:52,555 basehttp "GET /api/cache/stats/ HTTP/1.1" 404 2375
INFO 2025-07-12 15:13:07,902 basehttp "GET /blog/api/cache/stats/ HTTP/1.1" 200 79
INFO 2025-07-12 15:13:10,460 basehttp "GET /blog/api/cache/stats/ HTTP/1.1" 200 79
WARNING 2025-07-12 15:13:44,732 log Not Found: /blog/article/
WARNING 2025-07-12 15:13:44,732 basehttp "GET /blog/article/ HTTP/1.1" 404 3371
INFO 2025-07-12 15:13:48,248 basehttp "GET /blog/article/1 HTTP/1.1" 301 0
ERROR 2025-07-12 15:13:48,303 log Internal Server Error: /blog/article/1/
Traceback (most recent call last):
  File "D:\Desktop\个人项目集合\面试测试题\DjangoView\.venv\Lib\site-packages\django\db\backends\utils.py", line 105, in _execute
    return self.cursor.execute(sql, params)
           ~~~~~~~~~~~~~~~~~~~^^^^^^^^^^^^^
  File "D:\Desktop\个人项目集合\面试测试题\DjangoView\.venv\Lib\site-packages\django\db\backends\sqlite3\base.py", line 360, in execute
    return super().execute(query, params)
           ~~~~~~~~~~~~~~~^^^^^^^^^^^^^^^
sqlite3.OperationalError: no such table: blog_article

The above exception was the direct cause of the following exception:

Traceback (most recent call last):
  File "D:\Desktop\个人项目集合\面试测试题\DjangoView\.venv\Lib\site-packages\django\core\handlers\exception.py", line 55, in inner
    response = get_response(request)
  File "D:\Desktop\个人项目集合\面试测试题\DjangoView\.venv\Lib\site-packages\django\core\handlers\base.py", line 197, in _get_response
    response = wrapped_callback(request, *callback_args, **callback_kwargs)
  File "D:\Desktop\个人项目集合\面试测试题\DjangoView\.venv\Lib\site-packages\django\views\generic\base.py", line 105, in view
    return self.dispatch(request, *args, **kwargs)
           ~~~~~~~~~~~~~^^^^^^^^^^^^^^^^^^^^^^^^^^
  File "D:\Desktop\个人项目集合\面试测试题\DjangoView\.venv\Lib\site-packages\django\views\generic\base.py", line 144, in dispatch
    return handler(request, *args, **kwargs)
  File "D:\Desktop\个人项目集合\面试测试题\DjangoView\blog\views.py", line 23, in get
    article = get_object_or_404(Article, id=article_id)
  File "D:\Desktop\个人项目集合\面试测试题\DjangoView\.venv\Lib\site-packages\django\shortcuts.py", line 90, in get_object_or_404
    return queryset.get(*args, **kwargs)
           ~~~~~~~~~~~~^^^^^^^^^^^^^^^^^
  File "D:\Desktop\个人项目集合\面试测试题\DjangoView\.venv\Lib\site-packages\django\db\models\query.py", line 629, in get
    num = len(clone)
  File "D:\Desktop\个人项目集合\面试测试题\DjangoView\.venv\Lib\site-packages\django\db\models\query.py", line 366, in __len__
    self._fetch_all()
    ~~~~~~~~~~~~~~~^^
  File "D:\Desktop\个人项目集合\面试测试题\DjangoView\.venv\Lib\site-packages\django\db\models\query.py", line 1949, in _fetch_all
    self._result_cache = list(self._iterable_class(self))
                         ~~~~^^^^^^^^^^^^^^^^^^^^^^^^^^^^
  File "D:\Desktop\个人项目集合\面试测试题\DjangoView\.venv\Lib\site-packages\django\db\models\query.py", line 91, in __iter__
    results = compiler.execute_sql(
        chunked_fetch=self.chunked_fetch, chunk_size=self.chunk_size
    )
  File "D:\Desktop\个人项目集合\面试测试题\DjangoView\.venv\Lib\site-packages\django\db\models\sql\compiler.py", line 1623, in execute_sql
    cursor.execute(sql, params)
    ~~~~~~~~~~~~~~^^^^^^^^^^^^^
  File "D:\Desktop\个人项目集合\面试测试题\DjangoView\.venv\Lib\site-packages\django\db\backends\utils.py", line 122, in execute
    return super().execute(sql, params)
           ~~~~~~~~~~~~~~~^^^^^^^^^^^^^
  File "D:\Desktop\个人项目集合\面试测试题\DjangoView\.venv\Lib\site-packages\django\db\backends\utils.py", line 79, in execute
    return self._execute_with_wrappers(
           ~~~~~~~~~~~~~~~~~~~~~~~~~~~^
        sql, params, many=False, executor=self._execute
        ^^^^^^^^^^^^^^^^^^^^^^^^^^^^^^^^^^^^^^^^^^^^^^^
    )
    ^
  File "D:\Desktop\个人项目集合\面试测试题\DjangoView\.venv\Lib\site-packages\django\db\backends\utils.py", line 92, in _execute_with_wrappers
    return executor(sql, params, many, context)
  File "D:\Desktop\个人项目集合\面试测试题\DjangoView\.venv\Lib\site-packages\django\db\backends\utils.py", line 100, in _execute
    with self.db.wrap_database_errors:
         ^^^^^^^^^^^^^^^^^^^^^^^^^^^^
  File "D:\Desktop\个人项目集合\面试测试题\DjangoView\.venv\Lib\site-packages\django\db\utils.py", line 91, in __exit__
    raise dj_exc_value.with_traceback(traceback) from exc_value
  File "D:\Desktop\个人项目集合\面试测试题\DjangoView\.venv\Lib\site-packages\django\db\backends\utils.py", line 105, in _execute
    return self.cursor.execute(sql, params)
           ~~~~~~~~~~~~~~~~~~~^^^^^^^^^^^^^
  File "D:\Desktop\个人项目集合\面试测试题\DjangoView\.venv\Lib\site-packages\django\db\backends\sqlite3\base.py", line 360, in execute
    return super().execute(query, params)
           ~~~~~~~~~~~~~~~^^^^^^^^^^^^^^^
django.db.utils.OperationalError: no such table: blog_article
ERROR 2025-07-12 15:13:48,317 basehttp "GET /blog/article/1/ HTTP/1.1" 500 151306
ERROR 2025-07-12 15:14:26,655 log Internal Server Error: /blog/article/1/
Traceback (most recent call last):
  File "D:\Desktop\个人项目集合\面试测试题\DjangoView\.venv\Lib\site-packages\django\db\backends\utils.py", line 105, in _execute
    return self.cursor.execute(sql, params)
           ~~~~~~~~~~~~~~~~~~~^^^^^^^^^^^^^
  File "D:\Desktop\个人项目集合\面试测试题\DjangoView\.venv\Lib\site-packages\django\db\backends\sqlite3\base.py", line 360, in execute
    return super().execute(query, params)
           ~~~~~~~~~~~~~~~^^^^^^^^^^^^^^^
sqlite3.OperationalError: no such table: blog_article

The above exception was the direct cause of the following exception:

Traceback (most recent call last):
  File "D:\Desktop\个人项目集合\面试测试题\DjangoView\.venv\Lib\site-packages\django\core\handlers\exception.py", line 55, in inner
    response = get_response(request)
  File "D:\Desktop\个人项目集合\面试测试题\DjangoView\.venv\Lib\site-packages\django\core\handlers\base.py", line 197, in _get_response
    response = wrapped_callback(request, *callback_args, **callback_kwargs)
  File "D:\Desktop\个人项目集合\面试测试题\DjangoView\.venv\Lib\site-packages\django\views\generic\base.py", line 105, in view
    return self.dispatch(request, *args, **kwargs)
           ~~~~~~~~~~~~~^^^^^^^^^^^^^^^^^^^^^^^^^^
  File "D:\Desktop\个人项目集合\面试测试题\DjangoView\.venv\Lib\site-packages\django\views\generic\base.py", line 144, in dispatch
    return handler(request, *args, **kwargs)
  File "D:\Desktop\个人项目集合\面试测试题\DjangoView\blog\views.py", line 23, in get
    article = get_object_or_404(Article, id=article_id)
  File "D:\Desktop\个人项目集合\面试测试题\DjangoView\.venv\Lib\site-packages\django\shortcuts.py", line 90, in get_object_or_404
    return queryset.get(*args, **kwargs)
           ~~~~~~~~~~~~^^^^^^^^^^^^^^^^^
  File "D:\Desktop\个人项目集合\面试测试题\DjangoView\.venv\Lib\site-packages\django\db\models\query.py", line 629, in get
    num = len(clone)
  File "D:\Desktop\个人项目集合\面试测试题\DjangoView\.venv\Lib\site-packages\django\db\models\query.py", line 366, in __len__
    self._fetch_all()
    ~~~~~~~~~~~~~~~^^
  File "D:\Desktop\个人项目集合\面试测试题\DjangoView\.venv\Lib\site-packages\django\db\models\query.py", line 1949, in _fetch_all
    self._result_cache = list(self._iterable_class(self))
                         ~~~~^^^^^^^^^^^^^^^^^^^^^^^^^^^^
  File "D:\Desktop\个人项目集合\面试测试题\DjangoView\.venv\Lib\site-packages\django\db\models\query.py", line 91, in __iter__
    results = compiler.execute_sql(
        chunked_fetch=self.chunked_fetch, chunk_size=self.chunk_size
    )
  File "D:\Desktop\个人项目集合\面试测试题\DjangoView\.venv\Lib\site-packages\django\db\models\sql\compiler.py", line 1623, in execute_sql
    cursor.execute(sql, params)
    ~~~~~~~~~~~~~~^^^^^^^^^^^^^
  File "D:\Desktop\个人项目集合\面试测试题\DjangoView\.venv\Lib\site-packages\django\db\backends\utils.py", line 122, in execute
    return super().execute(sql, params)
           ~~~~~~~~~~~~~~~^^^^^^^^^^^^^
  File "D:\Desktop\个人项目集合\面试测试题\DjangoView\.venv\Lib\site-packages\django\db\backends\utils.py", line 79, in execute
    return self._execute_with_wrappers(
           ~~~~~~~~~~~~~~~~~~~~~~~~~~~^
        sql, params, many=False, executor=self._execute
        ^^^^^^^^^^^^^^^^^^^^^^^^^^^^^^^^^^^^^^^^^^^^^^^
    )
    ^
  File "D:\Desktop\个人项目集合\面试测试题\DjangoView\.venv\Lib\site-packages\django\db\backends\utils.py", line 92, in _execute_with_wrappers
    return executor(sql, params, many, context)
  File "D:\Desktop\个人项目集合\面试测试题\DjangoView\.venv\Lib\site-packages\django\db\backends\utils.py", line 100, in _execute
    with self.db.wrap_database_errors:
         ^^^^^^^^^^^^^^^^^^^^^^^^^^^^
  File "D:\Desktop\个人项目集合\面试测试题\DjangoView\.venv\Lib\site-packages\django\db\utils.py", line 91, in __exit__
    raise dj_exc_value.with_traceback(traceback) from exc_value
  File "D:\Desktop\个人项目集合\面试测试题\DjangoView\.venv\Lib\site-packages\django\db\backends\utils.py", line 105, in _execute
    return self.cursor.execute(sql, params)
           ~~~~~~~~~~~~~~~~~~~^^^^^^^^^^^^^
  File "D:\Desktop\个人项目集合\面试测试题\DjangoView\.venv\Lib\site-packages\django\db\backends\sqlite3\base.py", line 360, in execute
    return super().execute(query, params)
           ~~~~~~~~~~~~~~~^^^^^^^^^^^^^^^
django.db.utils.OperationalError: no such table: blog_article
ERROR 2025-07-12 15:14:26,668 basehttp "GET /blog/article/1/ HTTP/1.1" 500 151443
INFO 2025-07-12 15:16:01,285 autoreload D:\Desktop\个人项目集合\面试测试题\DjangoView\blog\models.py changed, reloading.
